[0m13:15:27.544006 [debug] [MainThread]: Sending event: {'category': 'dbt', 'action': 'invocation', 'label': 'start', 'context': [<snowplow_tracker.self_describing_json.SelfDescribingJson object at 0x105a03620>, <snowplow_tracker.self_describing_json.SelfDescribingJson object at 0x10741b9d0>, <snowplow_tracker.self_describing_json.SelfDescribingJson object at 0x10741bb10>]}


============================== 13:15:27.547471 | a5fac7e6-20ce-424b-92cd-6534b655c0a3 ==============================
[0m13:15:27.547471 [info ] [MainThread]: Running with dbt=1.10.6
[0m13:15:27.547725 [debug] [MainThread]: running dbt with arguments {'printer_width': '80', 'indirect_selection': 'eager', 'write_json': 'True', 'log_cache_events': 'False', 'partial_parse': 'True', 'cache_selected_only': 'False', 'warn_error': 'None', 'version_check': 'True', 'debug': 'False', 'log_path': 'logs', 'profiles_dir': '/Users/blakerodenbeck/.dbt', 'fail_fast': 'False', 'use_colors': 'True', 'use_experimental_parser': 'False', 'no_print': 'None', 'quiet': 'False', 'empty': 'None', 'warn_error_options': 'WarnErrorOptionsV2(error=[], warn=[], silence=[])', 'introspect': 'True', 'invocation_command': 'dbt init trading_analytics', 'log_format': 'default', 'target_path': 'None', 'static_parser': 'True', 'send_anonymous_usage_stats': 'True'}
[0m13:15:27.557567 [info ] [MainThread]: Creating dbt configuration folder at /Users/blakerodenbeck/.dbt
[0m13:15:27.558492 [debug] [MainThread]: Starter project path: /Users/blakerodenbeck/Projects/Finance/.venv/lib/python3.13/site-packages/dbt/include/starter_project
[0m13:15:27.561316 [info ] [MainThread]: 
Your new dbt project "trading_analytics" was created!

For more information on how to configure the profiles.yml file,
please consult the dbt documentation here:

  https://docs.getdbt.com/docs/configure-your-profile

One more thing:

Need help? Don't hesitate to reach out to us via GitHub issues or on Slack:

  https://community.getdbt.com/

Happy modeling!

[0m13:15:27.561466 [info ] [MainThread]: Setting up your profile.
[0m13:30:49.392907 [error] [MainThread]: Encountered an error:
list index out of range
[0m13:30:49.401830 [error] [MainThread]: Traceback (most recent call last):
  File "/Users/blakerodenbeck/Projects/Finance/.venv/lib/python3.13/site-packages/dbt/cli/requires.py", line 178, in wrapper
    result, success = func(*args, **kwargs)
                      ~~~~^^^^^^^^^^^^^^^^^
  File "/Users/blakerodenbeck/Projects/Finance/.venv/lib/python3.13/site-packages/dbt/cli/requires.py", line 128, in wrapper
    return func(*args, **kwargs)
  File "/Users/blakerodenbeck/Projects/Finance/.venv/lib/python3.13/site-packages/dbt/cli/main.py", line 483, in init
    results = task.run()
  File "/Users/blakerodenbeck/Projects/Finance/.venv/lib/python3.13/site-packages/dbt/task/init.py", line 346, in run
    self.setup_profile(profile_name)
    ~~~~~~~~~~~~~~~~~~^^^^^^^^^^^^^^
  File "/Users/blakerodenbeck/Projects/Finance/.venv/lib/python3.13/site-packages/dbt/task/init.py", line 261, in setup_profile
    adapter = self.ask_for_adapter_choice()
  File "/Users/blakerodenbeck/Projects/Finance/.venv/lib/python3.13/site-packages/dbt/task/init.py", line 243, in ask_for_adapter_choice
    return available_adapters[numeric_choice - 1]
           ~~~~~~~~~~~~~~~~~~^^^^^^^^^^^^^^^^^^^^
IndexError: list index out of range

[0m13:30:49.436481 [debug] [MainThread]: Resource report: {"command_name": "init", "command_success": false, "command_wall_clock_time": 921.9208, "process_in_blocks": "0", "process_kernel_time": 0.113878, "process_mem_max_rss": "109592576", "process_out_blocks": "0", "process_user_time": 0.523414}
[0m13:30:49.437197 [debug] [MainThread]: Command `dbt init` failed at 13:30:49.437075 after 921.92 seconds
[0m13:30:49.437866 [debug] [MainThread]: Sending event: {'category': 'dbt', 'action': 'invocation', 'label': 'end', 'context': [<snowplow_tracker.self_describing_json.SelfDescribingJson object at 0x1074c0b00>, <snowplow_tracker.self_describing_json.SelfDescribingJson object at 0x1074c6330>, <snowplow_tracker.self_describing_json.SelfDescribingJson object at 0x1072b6690>]}
[0m13:30:49.438239 [debug] [MainThread]: Flushing usage events
[0m13:30:50.069966 [debug] [MainThread]: An error was encountered while trying to flush usage events
[0m16:08:57.540017 [debug] [MainThread]: Sending event: {'category': 'dbt', 'action': 'invocation', 'label': 'start', 'context': [<snowplow_tracker.self_describing_json.SelfDescribingJson object at 0x103477620>, <snowplow_tracker.self_describing_json.SelfDescribingJson object at 0x1049839d0>, <snowplow_tracker.self_describing_json.SelfDescribingJson object at 0x104983b10>]}


============================== 16:08:57.542352 | 24f70b29-3a4b-4be4-934a-c5d5601a09c3 ==============================
[0m16:08:57.542352 [info ] [MainThread]: Running with dbt=1.10.6
[0m16:08:57.542613 [debug] [MainThread]: running dbt with arguments {'printer_width': '80', 'indirect_selection': 'eager', 'log_cache_events': 'False', 'write_json': 'True', 'partial_parse': 'True', 'cache_selected_only': 'False', 'warn_error': 'None', 'debug': 'False', 'profiles_dir': '/Users/blakerodenbeck/.dbt', 'log_path': 'logs', 'version_check': 'True', 'fail_fast': 'False', 'use_colors': 'True', 'use_experimental_parser': 'False', 'no_print': 'None', 'quiet': 'False', 'empty': 'False', 'warn_error_options': 'WarnErrorOptionsV2(error=[], warn=[], silence=[])', 'invocation_command': 'dbt run -s stg_ohlcv_1m', 'static_parser': 'True', 'introspect': 'True', 'target_path': 'None', 'log_format': 'default', 'send_anonymous_usage_stats': 'True'}
[0m16:08:57.542876 [error] [MainThread]: Encountered an error:
Runtime Error
  No dbt_project.yml found at expected path /Users/blakerodenbeck/Projects/Finance/dbt_project.yml
  Verify that each entry within packages.yml (and their transitive dependencies) contains a file named dbt_project.yml
  
[0m16:08:57.544244 [debug] [MainThread]: Resource report: {"command_name": "run", "command_success": false, "command_wall_clock_time": 0.034376834, "process_in_blocks": "0", "process_kernel_time": 0.078037, "process_mem_max_rss": "107560960", "process_out_blocks": "0", "process_user_time": 0.452087}
[0m16:08:57.544442 [debug] [MainThread]: Command `dbt run` failed at 16:08:57.544406 after 0.03 seconds
[0m16:08:57.544568 [debug] [MainThread]: Sending event: {'category': 'dbt', 'action': 'invocation', 'label': 'end', 'context': [<snowplow_tracker.self_describing_json.SelfDescribingJson object at 0x10487f360>, <snowplow_tracker.self_describing_json.SelfDescribingJson object at 0x1049adfd0>, <snowplow_tracker.self_describing_json.SelfDescribingJson object at 0x1048199d0>]}
[0m16:08:57.544684 [debug] [MainThread]: Flushing usage events
[0m16:08:57.847806 [debug] [MainThread]: An error was encountered while trying to flush usage events
